Workbook

Sheet Instruction
A1: Full period and lookback period calculations are similar to each other.
A2: From RAW_PRICES sheet
A3: - calculate the normal prices for each ticker
A4: - average the normalized ticker price for the portfolio normal price
A5: - calculate portfolio normal simple returns
A6: - calculate the `drift weight` of the portfolio tickers
A7: - use sumproduct to calculate portf_atrp and portf_trp
A8: - repeat the process for benchmark SPY
A9: - verify these calculated values are same as DAILY_AUDIT ``Port_Value, Port_ATRP, Port_TRP, Bench_Value, Bench_ATRP, Bench_TRP, Port_Ret, Bench_Ret``
A10: From DAILY_AUDIT sheet
A11: - gain = ln(price_end / price_start)
A12: - annulaized sharpe = avg_return / stdev.s_return * sqrt(252)
... A22: - repeat the process for Full period using the renormalized ticker prices, and renormalized drift weights

Sheet OVERVIEW
B1: Value
A2: mode | B2: Ranking
A3: start_date | B3: 2025-12-10 00:00:00
A4: lookback_period | B4: 10
A5: holding_period | B5: 5
A6: metric | B6: Sharpe (ATRP)
A7: benchmark_ticker | B7: SPY
A8: rank_start | B8: 11
A9: rank_end | B9: 12
A10: quality_thresholds | B10: {'min_median_dollar_volume': 1000000, 'min_liquidity_percentile': 0.4, 'max_stale_pct': 0.05, 'max_same_vol_count': 10}
A11: manual_tickers | B11: []
A12: debug | B12: True
A13: universe_subset | B13: None | C13: verification_calc | D13: difference
A14: full_p_gain | B14: 0.16922101500078077 | C14: =DAILY_AUDIT!B21 -> 0.16922102 | D14: =B14-C14 -> -3.8857806e-16
A15: full_p_sharpe | B15: 5.045514355626267 | C15: =DAILY_AUDIT!H24 -> 5.0455144 | D15: =B15-C15 -> 0
A16: full_p_sharpe_atrp | B16: 0.2878131597497803 | C16: =DAILY_AUDIT!C25 -> 0.28781316 | D16: =B16-C16 -> 0
A17: full_p_sharpe_trp | B17: 0.2420330170291394 | C17: =DAILY_AUDIT!D25 -> 0.24203302 | D17: =B17-C17 -> -3.8857806e-16
A18: lookback_p_gain | B18: 0.22682862617730912 | C18: =DAILY_AUDIT!B28 -> 0.22682863 | D18: =B18-C18 -> 0
A19: lookback_p_sharpe | B19: 10.057279489726138 | C19: =DAILY_AUDIT!H31 -> 10.057279 | D19: =B19-C19 -> -3.907985e-14
A20: lookback_p_sharpe_atrp | B20: 0.6313079069428091 | C20: =DAILY_AUDIT!C32 -> 0.63130791 | D20: =B20-C20 -> 0
A21: lookback_p_sharpe_trp | B21: 0.5073159025229343 | C21: =DAILY_AUDIT!D32 -> 0.5073159 | D21: =B21-C21 -> 0
A22: holding_p_gain | B22: -0.0513938187932114 | C22: =DAILY_AUDIT!K35 -> -0.051393819 | D22: =B22-C22 -> 0
A23: holding_p_sharpe | B23: -6.9657851757154186 | C23: =DAILY_AUDIT!L38 -> -6.9657852 | D23: =B23-C23 -> 0
A24: holding_p_sharpe_atrp | B24: -0.2381302054551481 | C24: =DAILY_AUDIT!M39 -> -0.23813021 | D24: =B24-C24 -> 0
A25: holding_p_sharpe_trp | B25: -0.21551451815185263 | C25: =DAILY_AUDIT!N39 -> -0.21551452 | D25: =B25-C25 -> 6.1062266e-16
A26: full_b_gain | B26: 0.0021461847425559458 | C26: =DAILY_AUDIT!E21 -> 0.0021461847 | D26: =B26-C26 -> 4.37584e-16
A27: full_b_sharpe | B27: 0.4185748763655909 | C27: =DAILY_AUDIT!I24 -> 0.41857488 | D27: =B27-C27 -> 7.2164497e-16
A28: full_b_sharpe_atrp | B28: 0.012770004741758323 | C28: =DAILY_AUDIT!F25 -> 0.012770005 | D28: =B28-C28 -> 2.2551405e-17
A29: full_b_sharpe_trp | B29: 0.016790501998420564 | C29: =DAILY_AUDIT!G25 -> 0.016790502 | D29: =B29-C29 -> 0
A30: lookback_b_gain | B30: 0.01842129267648779 | C30: =DAILY_AUDIT!E28 -> 0.018421293 | D30: =B30-C30 -> 1.2836954e-16
A31: lookback_b_sharpe | B31: 7.519907593864996 | C31: =DAILY_AUDIT!I31 -> 7.5199076 | D31: =B31-C31 -> 0
A32: lookback_b_sharpe_atrp | B32: 0.15231178870750767 | C32: =DAILY_AUDIT!F32 -> 0.15231179 | D32: =B32-C32 -> -6.6613381e-16
A33: lookback_b_sharpe_trp | B33: 0.26028737755209663 | C33: =DAILY_AUDIT!G32 -> 0.26028738 | D33: =B33-C33 -> -6.1062266e-16
A34: holding_b_gain | B34: -0.018600480298115105 | C34: =DAILY_AUDIT!E35 -> -0.01860048 | D34: =B34-C34 -> 6.800116e-16
A35: holding_b_sharpe | B35: -7.6347586991434975 | C35: =DAILY_AUDIT!I38 -> -7.6347587 | D35: =B35-C35 -> 1.2434498e-14
A36: holding_b_sharpe_atrp | B36: -0.3362632637536792 | C36: =DAILY_AUDIT!F39 -> -0.33626326 | D36: =B36-C36 -> 4.4408921e-16
A37: holding_b_sharpe_trp | B37: -0.3034961199255011 | C37: =DAILY_AUDIT!G39 -> -0.30349612 | D37: =B37-C37 -> 0

Sheet DAILY_AUDIT
A1: Date | B1: Port_Value | C1: Port_ATRP | D1: Port_TRP | E1: Bench_Value | F1: Bench_ATRP | G1: Bench_TRP | H1: Port_Ret | I1: Bench_Ret | J1: Period_Label | K1: portf_norm Holding Period | L1: portf_ret Holding Period | M1: portf_atrp Holding Period | N1: portf_trp Holding Period
A2: 45986 | B2: 1 | C2: 0.03887448 | D2: 0.033483487 | E2: 1 | F2: 0.014713566 | G2: 0.0173781 | J2: LOOKBACK
A3: 45987 | B3: 1.0129561 | C3: 0.03768643 | D3: 0.028705638 | E3: 1.0069046 | F3: 0.014270991 | G3: 0.0098291519 | H3: 0.012956096 | I3: 0.0069045854 | J3: LOOKBACK
A4: 45989 | B4: 1.0500417 | C4: 0.036820481 | D4: 0.042866383 | E4: 1.0124006 | F4: 0.013596708 | G4: 0.0058381777 | H4: 0.036611303 | I4: 0.0054583445 | J4: LOOKBACK
A5: 45992 | B5: 1.0641709 | C5: 0.03682114 | D5: 0.043185018 | E5: 1.0077782 | F5: 0.013171749 | G5: 0.0068365509 | H5: 0.013455767 | I5: -0.0045657543 | J5: LOOKBACK
A6: 45993 | B6: 1.0787749 | C6: 0.035960088 | D6: 0.031246511 | E6: 1.0096444 | F6: 0.012678802 | G6: 0.0065869832 | H6: 0.013723371 | I6: 0.0018517809 | J6: LOOKBACK
A7: 45994 | B7: 1.0933633 | C7: 0.035171934 | D7: 0.031163414 | E7: 1.0131406 | F7: 0.012277787 | G7: 0.0076333639 | H7: 0.013523187 | I7: 0.0034627282 | J7: LOOKBACK
A8: 45995 | B8: 1.069535 | C8: 0.036000485 | D8: 0.036584838 | E8: 1.013882 | F8: 0.011813055 | G8: 0.0058882666 | H8: -0.021793607 | I8: 0.00073180568 | J8: LOOKBACK
A9: 45996 | B9: 1.1974041 | C9: 0.039616791 | D9: 0.1366065 | E9: 1.0158076 | F9: 0.01136513 | G9: 0.0058332236 | H9: 0.1195558 | I9: 0.0018992517 | J9: LOOKBACK
A10: 45999 | B10: 1.2150116 | C10: 0.038793077 | D10: 0.035548232 | E10: 1.0127557 | F10: 0.011114866 | G10: 0.0074161992 | H10: 0.014704676 | I10: -0.0030043735 | J10: LOOKBACK
A11: 46000 | B11: 1.2512862 | C11: 0.038047571 | D11: 0.042975885 | E11: 1.0118821 | F11: 0.010622692 | G11: 0.0040996846 | H11: 0.02985541 | I11: -0.00086265581 | J11: LOOKBACK
A12: 46001 | B12: 1.2546148 | C12: 0.037724499 | D12: 0.034836832 | E12: 1.018592 | F12: 0.010594669 | G12: 0.011140058 | H12: 0.0026601505 | I12: 0.0066311517 | J12: LOOKBACK
A13: 46002 | B13: 1.2481511 | C13: 0.038284899 | D13: 0.04303039 | E13: 1.0209634 | F13: 0.010548843 | G13: 0.010273016 | H13: -0.0051519755 | I13: 0.0023280781 | J13: HOLDING | K13: 1 | M13: 0.038157542 | N13: 0.042932205
A14: 46003 | B14: 1.1899809 | C14: 0.042515565 | D14: 0.073184836 | E14: 1.0099847 | F14: 0.010949589 | G14: 0.014668607 | H14: -0.046605072 | I14: -0.010753267 | J14: HOLDING | K14: 0.95361585 | L14: =K14/K13-1 -> -0.046384145 | M14: 0.042379195 | N14: 0.073132768
A15: 46006 | B15: 1.201245 | C15: 0.04204479 | D15: 0.041107428 | E15: 1.0084587 | F15: 0.01086597 | G15: 0.0095635339 | H15: 0.0094658001 | I15: -0.0015108474 | J15: HOLDING | K15: 0.9629998 | L15: =K15/K14-1 -> 0.0098403804 | M15: 0.041903065 | N15: 0.041081908
A16: 46007 | B16: 1.1839418 | C16: 0.041641569 | D16: 0.028411412 | E16: 1.005704 | F16: 0.010759286 | G16: 0.0089854773 | H16: -0.014404461 | I16: -0.0027315963 | J16: HOLDING | K16: 0.94925112 | L16: =K16/K15-1 -> -0.014276924 | M16: 0.041492165 | N16: 0.028260616
A17: 46008 | B17: 1.1740244 | C17: 0.042781154 | D17: 0.053022883 | E17: 0.99463769 | F17: 0.01108486 | G17: 0.013761125 | H17: -0.0083765404 | I17: -0.01100359 | J17: HOLDING | K17: 0.94190211 | L17: =K17/K16-1 -> -0.0077419103 | M17: 0.042604951 | N17: 0.052862609
A18: 46009 | B18: 1.1843819 | C18: 0.042028023 | D18: 0.03710092 | E18: 1.0021485 | F18: 0.011202102 | G18: 0.013806253 | H18: 0.0088221783 | I18: 0.0075512905 | J18: HOLDING | K18: 0.94990451 | L18: =K18/K17-1 -> 0.0084960013 | M18: 0.041869459 | N18: 0.036974051
A21: full pd gain | B21: =LN(B18/B2) -> 0.16922102 | E21: =LN(E18/E2) -> 0.0021461847
A22: full pd avg vol | C22: =AVERAGE(C3:C18) -> 0.038871156 | D22: =AVERAGE(D3:D18) -> 0.04622357 | F22: =AVERAGE(F3:F18) -> 0.011682319 | G22: =AVERAGE(G3:G18) -> 0.0088849794 | H22: =AVERAGE(H3:H18) -> 0.01118763 | I22: =AVERAGE(I3:I18) -> 0.00014918327
A23: full pd stdev.s | H23: =_xlfn.STDEV.S(H3:H18) -> 0.035199211 | I23: =_xlfn.STDEV.S(I3:I18) -> 0.0056577952
A24: full pd sharpe annual | H24: =H22/H23*SQRT(252) -> 5.0455144 | I24: =I22/I23*SQRT(252) -> 0.41857488
A25: full pd sharpe vol | C25: =H$22/C22 -> 0.28781316 | D25: =H$22/D22 -> 0.24203302 | F25: =I$22/F22 -> 0.012770005 | G25: =I$22/G22 -> 0.016790502
A28: lookback pd gain | B28: =LN(B12/B2) -> 0.22682863 | E28: =LN(E12/E2) -> 0.018421293
A29: lookback pd avg vol | C29: =AVERAGE(C3:C12) -> 0.037264249 | D29: =AVERAGE(D3:D12) -> 0.046371926 | F29: =AVERAGE(F3:F12) -> 0.012150645 | G29: =AVERAGE(G3:G12) -> 0.007110166 | H29: =AVERAGE(H3:H12) -> 0.023525215 | I29: =AVERAGE(I3:I12) -> 0.0018506865
A30: lookback pd stdev.s | H30: =_xlfn.STDEV.S(H3:H12) -> 0.037132429 | I30: =_xlfn.STDEV.S(I3:I12) -> 0.0039067949
A31: lookback pd sharpe annual | H31: =H29/H30*SQRT(252) -> 10.057279 | I31: =I29/I30*SQRT(252) -> 7.5199076
A32: lookback pd sharpe vol | C32: =H$29/C29 -> 0.63130791 | D32: =H$29/D29 -> 0.5073159 | F32: =I$29/F29 -> 0.15231179 | G32: =I$29/G29 -> 0.26028738
A35: holding pd gain | E35: =LN(E18/E13) -> -0.01860048 | K35: =LN(K18/K13) -> -0.051393819
A36: holding pd avg vol | F36: =AVERAGE(F14:F18) -> 0.010972361 | G36: =AVERAGE(G14:G18) -> 0.012156999 | I36: =AVERAGE(I14:I18) -> -0.0036896021 | L36: =AVERAGE(L14:L18) -> -0.01001332 | M36: =AVERAGE(M14:M18) -> 0.042049767 | N36: =AVERAGE(N14:N18) -> 0.04646239
A37: holding pd stdev.s | I37: =_xlfn.STDEV.S(I14:I18) -> 0.0076715741 | L37: =_xlfn.STDEV.S(L14:L18) -> 0.022819613
A38: holding pd sharpe annual | I38: =I36/I37*SQRT(252) -> -7.6347587 | L38: =L36/L37*SQRT(252) -> -6.9657852
A39: holding p sharpe vol | F39: =$I36/F36 -> -0.33626326 | G39: =$I36/G36 -> -0.30349612 | M39: =L36/M36 -> -0.23813021 | N39: =L36/N36 -> -0.21551452

Sheet Sheet2
A1: Date | B1: Port_Value | C1: Port_ATRP | D1: Port_TRP | E1: Bench_Value | F1: Bench_ATRP | G1: Bench_TRP | H1: Port_Ret | I1: Bench_Ret | J1: Period_Label | N1: equity.iloc[-1]: | O1: RAW_prices
A2: 45986 | B2: 1 | C2: 0.03887448 | D2: 0.033483487 | E2: 1 | F2: 0.014713566 | G2: 0.0173781 | J2: LOOKBACK | N2: 0.94990451 | O2: =RAW_PRICES!#REF! -> #REF! | Q2: Date | R2: PSLV | S2: RBRK | U2: 46002 | V2: 1 | W2: 1
A3: 45987 | B3: 1.0129561 | C3: 0.03768643 | D3: 0.028705638 | E3: 1.0069046 | F3: 0.014270991 | G3: 0.0098291519 | H3: 0.012956096 | I3: 0.0069045854 | J3: LOOKBACK | Q3: 45986 | R3: 17.05 | S3: 68.89 | U3: 46003 | V3: 0.953616 | W3: 0.95361585
A4: 45989 | B4: 1.0500417 | C4: 0.036820481 | D4: 0.042866383 | E4: 1.0124006 | F4: 0.013596708 | G4: 0.0058381777 | H4: 0.036611303 | I4: 0.0054583445 | J4: LOOKBACK | N4: m_gain: | Q4: 45987 | R4: 17.67 | S4: 68.17 | U4: 46006 | V4: 0.963 | W4: 0.9629998
A5: 45992 | B5: 1.0641709 | C5: 0.03682114 | D5: 0.043185018 | E5: 1.0077782 | F5: 0.013171749 | G5: 0.0068365509 | H5: 0.013455767 | I5: -0.0045657543 | J5: LOOKBACK | N5: -0.051393819 | Q5: 45989 | R5: 18.65 | S5: 69.32 | U5: 46007 | V5: 0.949251 | W5: 0.94925112
A6: 45993 | B6: 1.0787749 | C6: 0.035960088 | D6: 0.031246511 | E6: 1.0096444 | F6: 0.012678802 | G6: 0.0065869832 | H6: 0.013723371 | I6: 0.0018517809 | J6: LOOKBACK | Q6: 45992 | R6: 19.31 | S6: 68.6 | U6: 46003 | V6: 0.941902 | W6: 0.94190211
A7: 45994 | B7: 1.0933633 | C7: 0.035171934 | D7: 0.031163414 | E7: 1.0131406 | F7: 0.012277787 | G7: 0.0076333639 | H7: 0.013523187 | I7: 0.0034627282 | J7: LOOKBACK | Q7: 45993 | R7: 19.61 | S7: 69.4 | U7: 46009 | V7: 0.949905 | W7: 0.94990451
A8: 45995 | B8: 1.069535 | C8: 0.036000485 | D8: 0.036584838 | E8: 1.013882 | F8: 0.011813055 | G8: 0.0058882666 | H8: -0.021793607 | I8: 0.00073180568 | J8: LOOKBACK | N8: np.sqrt(252): | Q8: 45994 | R8: 19.61 | S8: 71.41
A9: 45996 | B9: 1.1974041 | C9: 0.039616791 | D9: 0.1366065 | E9: 1.0158076 | F9: 0.01136513 | G9: 0.0058332236 | H9: 0.1195558 | I9: 0.0018992517 | J9: LOOKBACK | N9: 15.874508 | Q9: 45995 | R9: 19.04 | S9: 70.43
A10: 45999 | B10: 1.2150116 | C10: 0.038793077 | D10: 0.035548232 | E10: 1.0127557 | F10: 0.011114866 | G10: 0.0074161992 | H10: 0.014704676 | I10: -0.0030043735 | J10: LOOKBACK | Q10: 45996 | R10: 19.48 | S10: 86.27
A11: 46000 | B11: 1.2512862 | C11: 0.038047571 | D11: 0.042975885 | E11: 1.0118821 | F11: 0.010622692 | G11: 0.0040996846 | H11: 0.02985541 | I11: -0.00086265581 | J11: LOOKBACK | N11: rets.mean(): | Q11: 45999 | R11: 19.38 | S11: 89.1
A12: 46001 | B12: 1.2546148 | C12: 0.037724499 | D12: 0.034836832 | E12: 1.018592 | F12: 0.010594669 | G12: 0.011140058 | H12: 0.0026601505 | I12: 0.0066311517 | J12: LOOKBACK | N12: -0.01001332 | Q12: 46000 | R12: 20.07 | S12: 91.31
A13: 46002 | B13: 1 | C13: 0.038284899 | D13: 0.04303039 | E13: 1.0209634 | F13: 0.010548843 | G13: 0.010273016 | I13: 0.0023280781 | J13: HOLDING | K13: 1.2481511 | L13: =K13/K$13 -> 1 | Q13: 46001 | R13: 20.53 | S13: 89.91
A14: 46003 | B14: 0.953616 | C14: 0.042515565 | D14: 0.073184836 | E14: 1.0099847 | F14: 0.010949589 | G14: 0.014668607 | H14: =B14/B13-1 -> -0.046384 | I14: -0.010753267 | J14: HOLDING | K14: 1.1899809 | L14: =K14/K$13 -> 0.95339493 | N14: rets.std(): | Q14: 46002 | R14: 21.01 | S14: 87.08
A15: 46006 | B15: 0.963 | C15: 0.04204479 | D15: 0.041107428 | E15: 1.0084587 | F15: 0.01086597 | G15: 0.0095635339 | H15: =B15/B14-1 -> 0.0098404389 | I15: -0.0015108474 | J15: HOLDING | K15: 1.201245 | L15: =K15/K$13 -> 0.96241957 | N15: 0.022819613 | Q15: 46003 | R15: 20.4 | S15: 81.53
A16: 46007 | B16: 0.949251 | C16: 0.041641569 | D16: 0.028411412 | E16: 1.005704 | F16: 0.010759286 | G16: 0.0089854773 | H16: =B16/B15-1 -> -0.014277259 | I16: -0.0027315963 | J16: HOLDING | K16: 1.1839418 | L16: =K16/K$13 -> 0.94855644 | Q16: 46006 | R16: 21.19 | S16: 79.89
A17: 46008 | B17: 0.941902 | C17: 0.042781154 | D17: 0.053022883 | E17: 0.99463769 | F17: 0.01108486 | G17: 0.013761125 | H17: =B17/B16-1 -> -0.0077418933 | I17: -0.01100359 | J17: HOLDING | K17: 1.1740244 | L17: =K17/K$13 -> 0.94061082 | N17: m_sharpe: | Q17: 46007 | R17: 21.09 | S17: 77.91
A18: 46009 | B18: 0.949905 | C18: 0.042028023 | D18: 0.03710092 | E18: 1.0021485 | F18: 0.011202102 | G18: 0.013806253 | H18: =B18/B17-1 -> 0.0084966377 | I18: 0.0075512905 | J18: HOLDING | K18: 1.1843819 | L18: =K18/K$13 -> 0.94890905 | N18: -6.9657852 | Q18: 46008 | R18: 21.92 | S18: 73.19
Q19: 46009 | R19: 21.6 | S19: 75.91
A21: full pd gain | B21: =LN(#REF!/B2) -> #REF! | E21: =LN(E18/E2) -> 0.0021461847 | N21: p_atrp.mean():
A22: full pd avg vol | C22: =AVERAGE(C3:C18) -> 0.038871156 | D22: =AVERAGE(D3:D18) -> 0.04622357 | F22: =AVERAGE(F3:F18) -> 0.011682319 | G22: =AVERAGE(G3:G18) -> 0.0088849794 | H22: =AVERAGE(H3:H18) -> 0.012345739 | I22: =AVERAGE(I3:I18) -> 0.00014918327 | N22: 0.042049767
A23: full pd stdev.s | H23: =_xlfn.STDEV.S(H3:H18) -> 0.036096828 | I23: =_xlfn.STDEV.S(I3:I18) -> 0.0056577952
A24: full pd sharpe annual | H24: =H22/H23*SQRT(252) -> 5.4293558 | I24: =I22/I23*SQRT(252) -> 0.41857488 | N24: m_s_atrp:
A25: full pd sharpe vol | C25: =H$22/C22 -> 0.31760667 | D25: =H$22/D22 -> 0.26708751 | F25: =I$22/F22 -> 0.012770005 | G25: =I$22/G22 -> 0.016790502 | N25: -0.23813021
A28: lookback pd gain | B28: =LN(B12/B2) -> 0.22682863 | E28: =LN(E12/E2) -> 0.018421293 | N28: p_trp.mean():
A29: lookback pd avg vol | C29: =AVERAGE(C3:C12) -> 0.037264249 | D29: =AVERAGE(D3:D12) -> 0.046371926 | F29: =AVERAGE(F3:F12) -> 0.012150645 | G29: =AVERAGE(G3:G12) -> 0.007110166 | H29: =AVERAGE(H3:H12) -> 0.023525215 | I29: =AVERAGE(I3:I12) -> 0.0018506865 | N29: 0.04646239
A30: lookback pd stdev.s | H30: =_xlfn.STDEV.S(H3:H12) -> 0.037132429 | I30: =_xlfn.STDEV.S(I3:I12) -> 0.0039067949
A31: lookback pd sharpe annual | H31: =H29/H30*SQRT(252) -> 10.057279 | I31: =I29/I30*SQRT(252) -> 7.5199076 | N31: m_s_trp:
A32: lookback pd sharpe vol | C32: =H$29/C29 -> 0.63130791 | D32: =H$29/D29 -> 0.5073159 | F32: =I$29/F29 -> 0.15231179 | G32: =I$29/G29 -> 0.26028738 | N32: -0.21551452
A35: holding pd gain | B35: =LN(#REF!/#REF!) -> #REF! | E35: =LN(E18/E13) -> -0.01860048
A36: holding pd avg vol | C36: =AVERAGE(C14:C18) -> 0.04220222 | D36: =AVERAGE(D14:D18) -> 0.046565496 | F36: =AVERAGE(F14:F18) -> 0.010972361 | G36: =AVERAGE(G14:G18) -> 0.012156999 | H36: =AVERAGE(H14:H18) -> -0.010013215 | I36: =AVERAGE(I14:I18) -> -0.0036896021
A37: holding pd stdev.s | H37: =_xlfn.STDEV.S(H14:H18) -> 0.022819713 | I37: =_xlfn.STDEV.S(I14:I18) -> 0.0076715741
A38: holding pd sharpe annual | H38: =H36/H37*SQRT(252) -> -6.9656819 | I38: =I36/I37*SQRT(252) -> -7.6347587
A39: holding p sharpe vol | C39: =H$36/C36 -> -0.2372675 | D39: =H$36/D36 -> -0.21503508 | F39: =$I36/F36 -> -0.33626326 | G39: =$I36/G36 -> -0.30349612

Sheet RAW_OHLCV_SAMPLES
A1: Adj Open | B1: Adj High | C1: Adj Low | D1: Adj Close | E1: Volume | F1: Ticker | G1: Date
A2: 666.66 | B2: 674.218 | C2: 662.522 | D2: 673.031 | E2: 81316678 | F2: SPY
A3: 675.634 | B3: 679.692 | C3: 674.726 | D3: 677.678 | E3: 72091994 | F3: SPY
A4: 678.854 | B4: 681.656 | C4: 678.495 | D4: 681.377 | E4: 49357418 | F4: SPY
A5: 676.81 | B5: 680.978 | C5: 676.74 | D5: 678.266 | E5: 61382043 | F5: SPY
A6: 679.911 | B6: 681.805 | C6: 677.329 | D6: 679.522 | E6: 63139823 | F6: SPY
A7: 678.565 | B7: 682.892 | C7: 677.687 | D7: 681.875 | E7: 57407635 | F7: SPY
A8: 683.281 | B8: 683.351 | C8: 679.333 | D8: 682.374 | E8: 62153417 | F8: SPY
A9: 683.45 | B9: 686.362 | C9: 682.563 | D9: 683.67 | E9: 79475152 | F9: SPY
A10: 684.567 | B10: 684.617 | C10: 679.562 | D10: 681.616 | E10: 55394702 | F10: SPY
A11: 681.137 | B11: 683.371 | C11: 680.579 | D11: 681.028 | E11: 58482402 | F11: SPY
A12: 680.549 | B12: 686.94 | C12: 679.303 | D12: 685.544 | E12: 85924447 | F12: SPY
A13: 683.121 | B13: 687.219 | C13: 680.16 | D13: 687.14 | E13: 86428338 | F13: SPY
... A18: 675.604 | B18: 678.734 | C18: 672.912 | D18: 674.477 | E18: 108971155 | F18: SPY
A19: 16.99 | B19: 17.11 | C19: 16.78 | D19: 17.05 | E19: 4058200 | F19: PSLV | G19: 45986
A20: 17.31 | B20: 17.7 | C20: 17.24 | D20: 17.67 | E20: 4712500 | F20: PSLV | G20: 45987
A21: 18.14 | B21: 18.7 | C21: 18.13 | D21: 18.65 | E21: 10225500 | F21: PSLV | G21: 45989
A22: 19.17 | B22: 19.61 | C22: 18.97 | D22: 19.31 | E22: 17521100 | F22: PSLV | G22: 45992
A23: 19.41 | B23: 19.62 | C23: 19.02 | D23: 19.61 | E23: 8208300 | F23: PSLV | G23: 45993
A24: 19.61 | B24: 19.73 | C24: 19.37 | D24: 19.61 | E24: 6397500 | F24: PSLV | G24: 45994
A25: 19.35 | B25: 19.37 | C25: 18.84 | D25: 19.04 | E25: 8842600 | F25: PSLV | G25: 45995
A26: 19.39 | B26: 19.71 | C26: 19.26 | D26: 19.48 | E26: 8286900 | F26: PSLV | G26: 45996
A27: 19.46 | B27: 19.49 | C27: 19.22 | D27: 19.38 | E27: 6133200 | F27: PSLV | G27: 45999
A28: 19.59 | B28: 20.1 | C28: 19.59 | D28: 20.07 | E28: 19259000 | F28: PSLV | G28: 46000
A29: 20.15 | B29: 20.58 | C29: 19.89 | D29: 20.53 | E29: 11003100 | F29: PSLV | G29: 46001
A30: 20.8 | B30: 21.27 | C30: 20.69 | D30: 21.01 | E30: 12335800 | F30: PSLV | G30: 46002
... A52: 75.51 | B52: 76.82 | C52: 74.42 | D52: 75.91 | E52: 5273200 | F52: RBRK | G52: 46009

Sheet RAW_PRICES
A1: Date | B1: PSLV | C1: RBRK | D1: SPY | E1: PSLV_norm | F1: RBRK_norm | G1: SPY_norm | H1: portf_norm | I1: PSLV_retn | J1: RBRK_retn | K1: portf_retn | L1: SPY_retn | M1: PSLV_wt | N1: RBRK_wt | O1: portf_norm | P1: PSLV_wt | Q1: RBRK_wt | R1: PSLV_atrp | S1: RBRK_atrp | T1: portf_atrp | U1: SPY_atrp | V1: PSLV_trp | W1: RBRK_trp | X1: portf_trp | Y1: SPY_trp
A2: 45986 | B2: 17.05 | C2: 68.89 | D2: 673.031 | E2: =B2/B$2 -> 1 | F2: =C2/C$2 -> 1 | G2: =D2/D$2 -> 1 | H2: =AVERAGE(E2:F2) -> 1 | M2: =E2/SUM($E2:$F2) -> 0.5 | N2: =F2/SUM($E2:$F2) -> 0.5 | O2: =SUMPRODUCT($E2:$F2,M$2:N$2) -> 1 | P2: =E2*$M$2/$O2 -> 0.5 | Q2: =F2*$M$2/$O2 -> 0.5 | R2: 0.029130327 | S2: 0.048618633 | T2: =SUMPRODUCT($M2:$N2,R2:S2) -> 0.03887448 | U2: 0.014713566 | V2: 0.019354839 | W2: 0.047612135 | X2: =SUMPRODUCT($M2:$N2,V2:W2) -> 0.033483487 | Y2: 0.0173781
A3: 45987 | B3: 17.67 | C3: 68.17 | D3: 677.678 | E3: =B3/B$2 -> 1.0363636 | F3: =C3/C$2 -> 0.98954856 | G3: =D3/D$2 -> 1.0069046 | H3: =AVERAGE(E3:F3) -> 1.0129561 | I3: =E3/E2-1 -> 0.036363636 | J3: =F3/F2-1 -> -0.010451444 | K3: =H3/H2-1 -> 0.012956096 | L3: =G3/G2-1 -> 0.0069045854 | M3: =E3/SUM($E3:$F3) -> 0.51155407 | N3: =F3/SUM($E3:$F3) -> 0.48844593 | O3: =SUMPRODUCT($E3:$F3,M$2:N$2) -> 1.0129561 | P3: =E3*$M$2/$O3 -> 0.51155407 | Q3: =F3*$M$2/$O3 -> 0.48844593 | R3: 0.028728018 | S3: 0.047068661 | T3: =SUMPRODUCT($M3:$N3,R3:S3) -> 0.03768643 | U3: 0.014270991 | V3: 0.036785512 | W3: 0.020243509 | X3: =SUMPRODUCT($M3:$N3,V3:W3) -> 0.028705638 | Y3: 0.0098291519
A4: 45989 | B4: 18.65 | C4: 69.32 | D4: 681.377 | E4: =B4/B$2 -> 1.0938416 | F4: =C4/C$2 -> 1.0062418 | G4: =D4/D$2 -> 1.0124006 | H4: =AVERAGE(E4:F4) -> 1.0500417 | I4: =E4/E3-1 -> 0.055461234 | J4: =F4/F3-1 -> 0.016869591 | K4: =H4/H3-1 -> 0.036611303 | L4: =G4/G3-1 -> 0.0054583445 | M4: =E4/SUM($E4:$F4) -> 0.52085627 | N4: =F4/SUM($E4:$F4) -> 0.47914373 | O4: =SUMPRODUCT($E4:$F4,M$2:N$2) -> 1.0500417 | P4: =E4*$M$2/$O4 -> 0.52085627 | Q4: =F4*$M$2/$O4 -> 0.47914373 | R4: 0.029219123 | S4: 0.045083586 | T4: =SUMPRODUCT($M4:$N4,R4:S4) -> 0.036820481 | U4: 0.013596708 | V4: 0.055227882 | W4: 0.029428736 | X4: =SUMPRODUCT($M4:$N4,V4:W4) -> 0.042866383 | Y4: 0.0058381777
A5: 45992 | B5: 19.31 | C5: 68.6 | D5: 678.266 | E5: =B5/B$2 -> 1.1325513 | F5: =C5/C$2 -> 0.99579039 | G5: =D5/D$2 -> 1.0077782 | H5: =AVERAGE(E5:F5) -> 1.0641709 | I5: =E5/E4-1 -> 0.03538874 | J5: =F5/F4-1 -> -0.010386613 | K5: =H5/H4-1 -> 0.013455767 | L5: =G5/G4-1 -> -0.0045657543 | M5: =E5/SUM($E5:$F5) -> 0.53212852 | N5: =F5/SUM($E5:$F5) -> 0.46787148 | O5: =SUMPRODUCT($E5:$F5,M$2:N$2) -> 1.0641709 | P5: =E5*$M$2/$O5 -> 0.53212852 | Q5: =F5*$M$2/$O5 -> 0.46787148 | R5: 0.029755775 | S5: 0.044856856 | T5: =SUMPRODUCT($M5:$N5,R5:S5) -> 0.03682114 | U5: 0.013171749 | V5: 0.049715173 | W5: 0.035758017 | X5: =SUMPRODUCT($M5:$N5,V5:W5) -> 0.043185018 | Y5: 0.0068365509
A6: 45993 | B6: 19.61 | C6: 69.4 | D6: 679.522 | E6: =B6/B$2 -> 1.1501466 | F6: =C6/C$2 -> 1.0074031 | G6: =D6/D$2 -> 1.0096444 | H6: =AVERAGE(E6:F6) -> 1.0787749 | I6: =E6/E5-1 -> 0.015535992 | J6: =F6/F5-1 -> 0.011661808 | K6: =H6/H5-1 -> 0.013723371 | L6: =G6/G5-1 -> 0.0018517809 | M6: =E6/SUM($E6:$F6) -> 0.53308001 | N6: =F6/SUM($E6:$F6) -> 0.46691999 | O6: =SUMPRODUCT($E6:$F6,M$2:N$2) -> 1.0787749 | P6: =E6*$M$2/$O6 -> 0.53308001 | Q6: =F6*$M$2/$O6 -> 0.46691999 | R6: 0.029393139 | S6: 0.043457538 | T6: =SUMPRODUCT($M6:$N6,R6:S6) -> 0.035960088 | U6: 0.012678802 | V6: 0.030596634 | W6: 0.031988473 | X6: =SUMPRODUCT($M6:$N6,V6:W6) -> 0.031246511 | Y6: 0.0065869832
A7: 45994 | B7: 19.61 | C7: 71.41 | D7: 681.875 | E7: =B7/B$2 -> 1.1501466 | F7: =C7/C$2 -> 1.0365801 | G7: =D7/D$2 -> 1.0131406 | H7: =AVERAGE(E7:F7) -> 1.0933633 | I7: =E7/E6-1 -> 0 | J7: =F7/F6-1 -> 0.028962536 | K7: =H7/H6-1 -> 0.013523187 | L7: =G7/G6-1 -> 0.0034627282 | M7: =E7/SUM($E7:$F7) -> 0.52596725 | N7: =F7/SUM($E7:$F7) -> 0.47403275 | O7: =SUMPRODUCT($E7:$F7,M$2:N$2) -> 1.0933633 | P7: =E7*$M$2/$O7 -> 0.52596725 | Q7: =F7*$M$2/$O7 -> 0.47403275 | R7: 0.028604913 | S7: 0.04245843 | T7: =SUMPRODUCT($M7:$N7,R7:S7) -> 0.035171934 | U7: 0.012277787 | V7: 0.018357981 | W7: 0.045371797 | X7: =SUMPRODUCT($M7:$N7,V7:W7) -> 0.031163414 | Y7: 0.0076333639
A8: 45995 | B8: 19.04 | C8: 70.43 | D8: 682.374 | E8: =B8/B$2 -> 1.1167155 | F8: =C8/C$2 -> 1.0223545 | G8: =D8/D$2 -> 1.013882 | H8: =AVERAGE(E8:F8) -> 1.069535 | I8: =E8/E7-1 -> -0.029066803 | J8: =F8/F7-1 -> -0.013723568 | K8: =H8/H7-1 -> -0.021793607 | L8: =G8/G7-1 -> 0.00073180568 | M8: =E8/SUM($E8:$F8) -> 0.52205656 | N8: =F8/SUM($E8:$F8) -> 0.47794344 | O8: =SUMPRODUCT($E8:$F8,M$2:N$2) -> 1.069535 | P8: =E8*$M$2/$O8 -> 0.52205656 | Q8: =F8*$M$2/$O8 -> 0.47794344 | R8: 0.030245538 | S8: 0.042286601 | T8: =SUMPRODUCT($M8:$N8,R8:S8) -> 0.036000485 | U8: 0.011813055 | V8: 0.040441176 | W8: 0.032372569 | X8: =SUMPRODUCT($M8:$N8,V8:W8) -> 0.036584838 | Y8: 0.0058882666
A9: 45996 | B9: 19.48 | C9: 86.27 | D9: 683.67 | E9: =B9/B$2 -> 1.142522 | F9: =C9/C$2 -> 1.2522863 | G9: =D9/D$2 -> 1.0158076 | H9: =AVERAGE(E9:F9) -> 1.1974041 | I9: =E9/E8-1 -> 0.023109244 | J9: =F9/F8-1 -> 0.22490416 | K9: =H9/H8-1 -> 0.1195558 | L9: =G9/G8-1 -> 0.0018992517 | M9: =E9/SUM($E9:$F9) -> 0.47708287 | N9: =F9/SUM($E9:$F9) -> 0.52291713 | O9: =SUMPRODUCT($E9:$F9,M$2:N$2) -> 1.1974041 | P9: =E9*$M$2/$O9 -> 0.47708287 | Q9: =F9*$M$2/$O9 -> 0.52291713 | R9: 0.029907508 | S9: 0.048475044 | T9: =SUMPRODUCT($M9:$N9,R9:S9) -> 0.039616791 | U9: 0.01136513 | V9: 0.034394251 | W9: 0.22985974 | X9: =SUMPRODUCT($M9:$N9,V9:W9) -> 0.1366065 | Y9: 0.0058332236
A10: 45999 | B10: 19.38 | C10: 89.1 | D10: 681.616 | E10: =B10/B$2 -> 1.1366569 | F10: =C10/C$2 -> 1.2933662 | G10: =D10/D$2 -> 1.0127557 | H10: =AVERAGE(E10:F10) -> 1.2150116 | I10: =E10/E9-1 -> -0.0051334702 | J10: =F10/F9-1 -> 0.032803987 | K10: =H10/H9-1 -> 0.014704676 | L10: =G10/G9-1 -> -0.0030043735 | M10: =E10/SUM($E10:$F10) -> 0.46775559 | N10: =F10/SUM($E10:$F10) -> 0.53224441 | O10: =SUMPRODUCT($E10:$F10,M$2:N$2) -> 1.2150116 | P10: =E10*$M$2/$O10 -> 0.46775559 | Q10: =F10*$M$2/$O10 -> 0.53224441 | R10: 0.02890969 | S10: 0.047478954 | T10: =SUMPRODUCT($M10:$N10,R10:S10) -> 0.038793077 | U10: 0.011114866 | V10: 0.013931889 | W10: 0.054545455 | X10: =SUMPRODUCT($M10:$N10,V10:W10) -> 0.035548232 | Y10: 0.0074161992
A11: 46000 | B11: 20.07 | C11: 91.31 | D11: 681.028 | E11: =B11/B$2 -> 1.1771261 | F11: =C11/C$2 -> 1.3254464 | G11: =D11/D$2 -> 1.0118821 | H11: =AVERAGE(E11:F11) -> 1.2512862 | I11: =E11/E10-1 -> 0.035603715 | J11: =F11/F10-1 -> 0.024803591 | K11: =H11/H10-1 -> 0.02985541 | L11: =G11/G10-1 -> -0.00086265581 | M11: =E11/SUM($E11:$F11) -> 0.47036644 | N11: =F11/SUM($E11:$F11) -> 0.52963356 | O11: =SUMPRODUCT($E11:$F11,M$2:N$2) -> 1.2512862 | P11: =E11*$M$2/$O11 -> 0.47036644 | Q11: =F11*$M$2/$O11 -> 0.52963356 | R11: 0.02848426 | S11: 0.046540726 | T11: =SUMPRODUCT($M11:$N11,R11:S11) -> 0.038047571 | U11: 0.010622692 | V11: 0.035874439 | W11: 0.049282663 | X11: =SUMPRODUCT($M11:$N11,V11:W11) -> 0.042975885 | Y11: 0.0040996846
A12: 46001 | B12: 20.53 | C12: 89.91 | D12: 685.544 | E12: =B12/B$2 -> 1.2041056 | F12: =C12/C$2 -> 1.3051241 | G12: =D12/D$2 -> 1.018592 | H12: =AVERAGE(E12:F12) -> 1.2546148 | I12: =E12/E11-1 -> 0.022919781 | J12: =F12/F11-1 -> -0.015332384 | K12: =H12/H11-1 -> 0.0026601505 | L12: =G12/G11-1 -> 0.0066311517 | M12: =E12/SUM($E12:$F12) -> 0.47987061 | N12: =F12/SUM($E12:$F12) -> 0.52012939 | O12: =SUMPRODUCT($E12:$F12,M$2:N$2) -> 1.2546148 | P12: =E12*$M$2/$O12 -> 0.47987061 | Q12: =F12*$M$2/$O12 -> 0.52012939 | R12: 0.028257701 | S12: 0.046458552 | T12: =SUMPRODUCT($M12:$N12,R12:S12) -> 0.037724499 | U12: 0.010594669 | V12: 0.033609352 | W12: 0.035969303 | X12: =SUMPRODUCT($M12:$N12,V12:W12) -> 0.034836832 | Y12: 0.011140058
A13: 46002 | B13: 21.01 | C13: 87.08 | D13: 687.14 | E13: =B13/B$2 -> 1.2322581 | F13: =C13/C$2 -> 1.2640441 | G13: =D13/D$2 -> 1.0209634 | H13: =AVERAGE(E13:F13) -> 1.2481511 | I13: =E13/E12-1 -> 0.023380419 | J13: =F13/F12-1 -> -0.03147592 | K13: =H13/H12-1 -> -0.0051519755 | L13: =G13/G12-1 -> 0.0023280781 | M13: =E13/SUM($E13:$F13) -> 0.49363337 | N13: =F13/SUM($E13:$F13) -> 0.50636663 | O13: =SUMPRODUCT($E13:$F13,M$2:N$2) -> 1.2481511 | P13: =E13*$M$2/$O13 -> 0.49363337 | Q13: =F13*$M$2/$O13 -> 0.50636663 | R13: 0.028155632 | S13: 0.048159451 | T13: =SUMPRODUCT($M13:$N13,R13:S13) -> 0.038284899 | U13: 0.010548843 | V13: 0.035221323 | W13: 0.050643087 | X13: =SUMPRODUCT($M13:$N13,V13:W13) -> 0.04303039 | Y13: 0.010273016
A14: 46003 | B14: 20.4 | C14: 81.53 | D14: 679.751 | E14: =B14/B$2 -> 1.1964809 | F14: =C14/C$2 -> 1.1834809 | G14: =D14/D$2 -> 1.0099847 | H14: =AVERAGE(E14:F14) -> 1.1899809 | I14: =E14/E13-1 -> -0.029033793 | J14: =F14/F13-1 -> -0.063734497 | K14: =H14/H13-1 -> -0.046605072 | L14: =G14/G13-1 -> -0.010753267 | M14: =E14/SUM($E14:$F14) -> 0.50273114 | N14: =F14/SUM($E14:$F14) -> 0.49726886 | O14: =SUMPRODUCT($E14:$F14,M$2:N$2) -> 1.1899809 | P14: =E14*$M$2/$O14 -> 0.50273114 | Q14: =F14*$M$2/$O14 -> 0.49726886 | R14: 0.031863263 | S14: 0.053284878 | T14: =SUMPRODUCT($M14:$N14,R14:S14) -> 0.042515565 | U14: 0.010949589 | V14: 0.069117647 | W14: 0.077296701 | X14: =SUMPRODUCT($M14:$N14,V14:W14) -> 0.073184836 | Y14: 0.014668607
... A18: 46009 | B18: 21.6 | C18: 75.91 | D18: 674.477 | E18: =B18/B$2 -> 1.2668622 | F18: =C18/C$2 -> 1.1019016 | G18: =D18/D$2 -> 1.0021485 | H18: =AVERAGE(E18:F18) -> 1.1843819 | I18: =E18/E17-1 -> -0.01459854 | J18: =F18/F17-1 -> 0.037163547 | K18: =H18/H17-1 -> 0.0088221783 | L18: =G18/G17-1 -> 0.0075512905 | M18: =E18/SUM($E18:$F18) -> 0.53481997 | N18: =F18/SUM($E18:$F18) -> 0.46518003 | O18: =SUMPRODUCT($E18:$F18,M$2:N$2) -> 1.1843819 | P18: =E18*$M$2/$O18 -> 0.53481997 | Q18: =F18*$M$2/$O18 -> 0.46518003 | R18: 0.03037568 | S18: 0.055424785 | T18: =SUMPRODUCT($M18:$N18,R18:S18) -> 0.042028023 | U18: 0.011202102 | V18: 0.027777778 | W18: 0.047819787 | X18: =SUMPRODUCT($M18:$N18,V18:W18) -> 0.03710092 | Y18: 0.013806253
A20: Holding Period
A21: 46002 | E21: =E13/E$13 -> 1 | F21: =F13/F$13 -> 1 | H21: =AVERAGE(E21:F21) -> 1 | M21: =E21/SUM($E21:$F21) -> 0.5 | N21: =F21/SUM($E21:$F21) -> 0.5 | R21: =R13 -> 0.028155632 | S21: =S13 -> 0.048159451 | T21: =SUMPRODUCT($M21:$N21,R21:S21) -> 0.038157542 | V21: =V13 -> 0.035221323 | W21: =W13 -> 0.050643087 | X21: =SUMPRODUCT($M21:$N21,V21:W21) -> 0.042932205
A22: 46003 | E22: =E14/E$13 -> 0.97096621 | F22: =F14/F$13 -> 0.9362655 | H22: =AVERAGE(E22:F22) -> 0.95361585 | K22: =H22/H21-1 -> -0.046384145 | M22: =E22/SUM($E22:$F22) -> 0.50909714 | N22: =F22/SUM($E22:$F22) -> 0.49090286 | R22: =R14 -> 0.031863263 | S22: =S14 -> 0.053284878 | T22: =SUMPRODUCT($M22:$N22,R22:S22) -> 0.042379195 | V22: =V14 -> 0.069117647 | W22: =W14 -> 0.077296701 | X22: =SUMPRODUCT($M22:$N22,V22:W22) -> 0.073132768
A23: 46006 | E23: =E15/E$13 -> 1.0085673 | F23: =F15/F$13 -> 0.91743225 | H23: =AVERAGE(E23:F23) -> 0.9629998 | K23: =H23/H22-1 -> 0.0098403804 | M23: =E23/SUM($E23:$F23) -> 0.52365917 | N23: =F23/SUM($E23:$F23) -> 0.47634083 | R23: =R15 -> 0.031282065 | S23: =S15 -> 0.053579126 | T23: =SUMPRODUCT($M23:$N23,R23:S23) -> 0.041903065 | V23: =V15 -> 0.03916942 | W23: =W15 -> 0.043184379 | X23: =SUMPRODUCT($M23:$N23,V23:W23) -> 0.041081908
A24: 46007 | E24: =E16/E$13 -> 1.0038077 | F24: =F16/F$13 -> 0.89469453 | H24: =AVERAGE(E24:F24) -> 0.94925112 | K24: =H24/H23-1 -> -0.014276924 | M24: =E24/SUM($E24:$F24) -> 0.52873665 | N24: =F24/SUM($E24:$F24) -> 0.47126335 | R24: =R16 -> 0.030404628 | S24: =S16 -> 0.053931893 | T24: =SUMPRODUCT($M24:$N24,R24:S24) -> 0.041492165 | V24: =V16 -> 0.017069701 | W24: =W16 -> 0.040816327 | X24: =SUMPRODUCT($M24:$N24,V24:W24) -> 0.028260616
A25: 46008 | E25: =E17/E$13 -> 1.0433127 | F25: =F17/F$13 -> 0.8404915 | H25: =AVERAGE(E25:F25) -> 0.94190211 | K25: =H25/H24-1 -> -0.0077419103 | M25: =E25/SUM($E25:$F25) -> 0.55383288 | N25: =F25/SUM($E25:$F25) -> 0.44616712 | R25: =R17 -> 0.03012916 | S25: =S17 -> 0.058091307 | T25: =SUMPRODUCT($M25:$N25,R25:S25) -> 0.042604951 | V25: =V17 -> 0.041514599 | W25: =W17 -> 0.066949037 | X25: =SUMPRODUCT($M25:$N25,V25:W25) -> 0.052862609
A26: 46009 | E26: =E18/E$13 -> 1.0280819 | F26: =F18/F$13 -> 0.87172715 | H26: =AVERAGE(E26:F26) -> 0.94990451 | K26: =H26/H25-1 -> 0.0084960013 | M26: =E26/SUM($E26:$F26) -> 0.54115011 | N26: =F26/SUM($E26:$F26) -> 0.45884989 | R26: =R18 -> 0.03037568 | S26: =S18 -> 0.055424785 | T26: =SUMPRODUCT($M26:$N26,R26:S26) -> 0.041869459 | V26: =V18 -> 0.027777778 | W26: =W18 -> 0.047819787 | X26: =SUMPRODUCT($M26:$N26,V26:W26) -> 0.036974051
E28: =SQRT(252) -> 15.874508
E29: =E12/E2-1 -> 0.20410557 | F29: =E29*E28 -> 3.2400755
E30: =LN(E12/E2) -> 0.18573703 | F30: =E30*E28 -> 2.9484839

Sheet RAW_ATRP_DATA
A1: Date | B1: PSLV | C1: RBRK | D1: SPY
A2: 45986 | B2: 0.029130327 | C2: 0.048618633 | D2: 0.014713566
A3: 45987 | B3: 0.028728018 | C3: 0.047068661 | D3: 0.014270991
A4: 45989 | B4: 0.029219123 | C4: 0.045083586 | D4: 0.013596708
A5: 45992 | B5: 0.029755775 | C5: 0.044856856 | D5: 0.013171749
A6: 45993 | B6: 0.029393139 | C6: 0.043457538 | D6: 0.012678802
A7: 45994 | B7: 0.028604913 | C7: 0.04245843 | D7: 0.012277787
A8: 45995 | B8: 0.030245538 | C8: 0.042286601 | D8: 0.011813055
A9: 45996 | B9: 0.029907508 | C9: 0.048475044 | D9: 0.01136513
A10: 45999 | B10: 0.02890969 | C10: 0.047478954 | D10: 0.011114866
A11: 46000 | B11: 0.02848426 | C11: 0.046540726 | D11: 0.010622692
A12: 46001 | B12: 0.028257701 | C12: 0.046458552 | D12: 0.010594669
A13: 46002 | B13: 0.028155632 | C13: 0.048159451 | D13: 0.010548843
... A18: 46009 | B18: 0.03037568 | C18: 0.055424785 | D18: 0.011202102

Sheet RAW_TRP_DATA
A1: Date | B1: PSLV | C1: RBRK | D1: SPY
A2: 45986 | B2: 0.019354839 | C2: 0.047612135 | D2: 0.0173781
A3: 45987 | B3: 0.036785512 | C3: 0.020243509 | D3: 0.0098291519
A4: 45989 | B4: 0.055227882 | C4: 0.029428736 | D4: 0.0058381777
A5: 45992 | B5: 0.049715173 | C5: 0.035758017 | D5: 0.0068365509
A6: 45993 | B6: 0.030596634 | C6: 0.031988473 | D6: 0.0065869832
A7: 45994 | B7: 0.018357981 | C7: 0.045371797 | D7: 0.0076333639
A8: 45995 | B8: 0.040441176 | C8: 0.032372569 | D8: 0.0058882666
A9: 45996 | B9: 0.034394251 | C9: 0.22985974 | D9: 0.0058332236
A10: 45999 | B10: 0.013931889 | C10: 0.054545455 | D10: 0.0074161992
A11: 46000 | B11: 0.035874439 | C11: 0.049282663 | D11: 0.0040996846
A12: 46001 | B12: 0.033609352 | C12: 0.035969303 | D12: 0.011140058
A13: 46002 | B13: 0.035221323 | C13: 0.050643087 | D13: 0.010273016
... A18: 46009 | B18: 0.027777778 | C18: 0.047819787 | D18: 0.013806253

Sheet RAW_DRIFTED_WEIGHTS
A1: Date | B1: PSLV | C1: RBRK
A2: 45986 | B2: 0.5 | C2: 0.5
A3: 45987 | B3: 0.51155407 | C3: 0.48844593
A4: 45989 | B4: 0.52085627 | C4: 0.47914373
A5: 45992 | B5: 0.53212852 | C5: 0.46787148
A6: 45993 | B6: 0.53308001 | C6: 0.46691999
A7: 45994 | B7: 0.52596725 | C7: 0.47403275
A8: 45995 | B8: 0.52205656 | C8: 0.47794344
A9: 45996 | B9: 0.47708287 | C9: 0.52291713
A10: 45999 | B10: 0.46775559 | C10: 0.53224441
A11: 46000 | B11: 0.47036644 | C11: 0.52963356
A12: 46001 | B12: 0.47987061 | C12: 0.52012939
A13: 46002 | B13: 0.49363337 | C13: 0.50636663
... A18: 46009 | B18: 0.53481997 | C18: 0.46518003

Sheet SURVIVAL_AUDIT
A1: Ticker | B1: ATR | C1: ATRP | D1: TRP | E1: RSI | F1: Mom_21 | G1: Consistency | H1: IR_63 | I1: Beta_63 | J1: DD_21 | K1: Ret_1d | L1: RollingStalePct | M1: RollMedDollarVol | N1: RollingSameVolCount | O1: Passed_Final
A2: A | B2: 3.9055126 | C2: 0.027270467 | D2: 0.022930719 | E2: 44.391141 | F2: -0.019746884 | G2: 0.2 | H2: 0.081838574 | I2: 0.89234959 | J2: -0.087343869 | K2: 0.020122659 | L2: 0 | M2: 2.2043892e+08 | N2: 0 | O2: TRUE
A3: AA | B3: 1.7308632 | C3: 0.038773818 | D3: 0.045026882 | E3: 66.977955 | F3: 0.15081206 | G3: 0.4 | H3: 0.15643231 | I3: 2.4515493 | J3: 0 | K3: 0.026915114 | L3: 0 | M3: 1.8563217e+08 | N3: 0 | O3: TRUE
A4: AAL | B4: 0.52416928 | C4: 0.034621485 | D4: 0.028401585 | E4: 69.988495 | F4: 0.13749061 | G4: 0.8 | H4: 0.082039306 | I4: 1.4879445 | J4: 0 | K4: 0.0073186959 | L4: 0 | M4: 696133264 | N4: 0 | O4: TRUE
A5: AAON | B5: 4.5563247 | C5: 0.055154638 | D5: 0.045151919 | E5: 33.404317 | F5: -0.21828574 | G5: 0.4 | H5: -0.0085352026 | I5: 1.8648808 | J5: -0.2040659 | K5: 0.011757502 | L5: 0 | M5: 76325204 | N5: 0 | O5: FALSE
A6: AAPL | B6: 4.9559362 | C6: 0.017793889 | D6: 0.011869926 | E6: 58.820908 | F6: 0.034701944 | G6: 0.2 | H6: 0.2157138 | I6: 0.89160998 | J6: -0.025891677 | K6: 0.0057705988 | L6: 0 | M6: 1.111291e+10 | N6: 0 | O6: TRUE
A7: ABBV | B7: 5.0843943 | C7: 0.022760883 | D7: 0.022114485 | E7: 47.574511 | F7: 0.029585553 | G7: 0.2 | H7: -0.0098802717 | I7: 0.038910614 | J7: -0.046976458 | K7: 0.0098232449 | L7: 0 | M7: 1.1191367e+09 | N7: 0 | O7: TRUE
A8: ABEV | B8: 0.059641489 | C8: 0.024343465 | D8: 0.032653061 | E8: 47.89265 | F8: 0.0040983607 | G8: 0.2 | H8: 0.024435935 | I8: 0.17311675 | J8: -0.064885496 | K8: -0.008097166 | L8: 0 | M8: 70374169 | N8: 0 | O8: FALSE
A9: ABNB | B9: 3.352476 | C9: 0.026279501 | D9: 0.034255703 | E9: 63.931648 | F9: 0.061314476 | G9: 0.8 | H9: -0.0068157811 | I9: 0.91758968 | J9: 0 | K9: 0.017385756 | L9: 0 | M9: 567842690 | N9: 0 | O9: TRUE
A10: ABT | B10: 2.4941004 | C10: 0.020454847 | D10: 0.019502674 | E10: 38.277864 | F10: -0.026537651 | G10: 0.4 | H10: -0.14723369 | I10: 0.1423133 | J10: -0.061570668 | K10: 0.010717927 | L10: 0 | M10: 7.3755381e+08 | N10: 0 | O10: TRUE
A11: ABVX | B11: 6.8259868 | C11: 0.053524557 | D11: 0.12114797 | E11: 66.012457 | F11: 0.20175273 | G11: 0.8 | H11: 0.18238055 | I11: -0.45758648 | J11: -0.005458941 | K11: 0.036492198 | L11: 0 | M11: 2908489 | N11: 1 | O11: FALSE
A12: ACGL | B12: 1.5400982 | C12: 0.016782154 | D12: 0.016781083 | E12: 51.900952 | F12: 0.022051453 | G12: 0.2 | H12: -0.051404764 | I12: -0.18144751 | J12: -0.027860169 | K12: -0.0016318538 | L12: 0 | M12: 163032223 | N12: 0 | O12: TRUE
A13: ACI | B13: 0.3911956 | C13: 0.023132612 | D13: 0.028726864 | E13: 36.619366 | F13: -0.024031303 | G13: 0.2 | H13: -0.083554093 | I13: 0.01496167 | J13: -0.069290039 | K13: -0.0098714256 | L13: 0 | M13: 1.1565288e+08 | N13: 0 | O13: TRUE
... A47: AKAM | B47: 2.4890237 | C47: 0.028791482 | D47: 0.017929439 | E47: 54.285516 | F47: -0.0076905418 | G47: 0.6 | H47: 0.037407304 | I47: 0.87288037 | J47: -0.046962849 | K47: 0.0092225076 | L47: 0 | M47: 1.4527652e+08 | N47: 0 | O47: TRUE
A48: AKRE | B48: 0.80092401 | C48: 0.012346601 | D48: 0.013257284 | E48: 48.62322 | F48: 0.012644396 | G48: 0.6 | H48: 0 | I48: 1 | J48: -0.0041449186 | K48: 0.0058923864 | O48: FALSE
A49: AL | B49: 0.17941703 | C49: 0.0028146938 | D49: 0.0015625245 | E49: 64.474545 | F49: 0.0059622632 | G49: 0.4 | H49: -0.083713135 | I49: 0.032781338 | J49: -0.0021836966 | K49: 0 | L49: 0 | M49: 47240308 | N49: 0 | O49: FALSE
A50: ALAB | B50: 13.311636 | C50: 0.08101291 | D50: 0.027928065 | E50: 52.126248 | F50: -0.054247726 | G50: 0.6 | H50: -0.093866362 | I50: 2.6426611 | J50: -0.065010811 | K50: -0.016548959 | L50: 0 | M50: 542068009 | N50: 0 | O50: TRUE
A51: ALB | B51: 6.2191393 | C51: 0.046827694 | D51: 0.038137476 | E51: 67.323809 | F51: 0.28606151 | G51: 0.8 | H51: 0.24698638 | I51: 1.9423087 | J51: 0 | K51: 0.030317841 | L51: 0 | M51: 2.2987058e+08 | N51: 0 | O51: TRUE
A52: ALC | B52: 1.6128987 | C52: 0.020108449 | D52: 0.02144371 | E52: 58.832208 | F52: 0.078236322 | G52: 0.4 | H52: -0.038461846 | I52: 0.74534907 | J52: -0.0064412238 | K52: 0.019575442 | L52: 0 | M52: 1.3521986e+08 | N52: 0 | O52: TRUE
A53: ALGN | B53: 4.9535564 | C53: 0.030098167 | D53: 0.046238911 | E53: 79.175434 | F53: 0.19062432 | G53: 1 | H53: 0.13571337 | I53: 1.3949093 | J53: 0 | K53: 0.03509434 | L53: 0 | M53: 169924492 | N53: 0 | O53: TRUE
A54: ALL | B54: 3.5434183 | C54: 0.017701426 | D54: 0.013023474 | E54: 40.720657 | F54: -0.0085879422 | G54: 0.4 | H54: -0.046086189 | I54: -0.045060831 | J54: -0.0568366 | K54: 0.00069486798 | L54: 0 | M54: 2.9054306e+08 | N54: 0 | O54: TRUE
A55: ALLE | B55: 3.1714676 | C55: 0.019784577 | D55: 0.022707424 | E55: 41.302651 | F55: -0.03942953 | G55: 0.2 | H55: -0.20674944 | I55: 0.51331365 | J55: -0.047986697 | K55: 0.017842403 | L55: 0 | M55: 1.2659966e+08 | N55: 0 | O55: TRUE
A56: ALLY | B56: 1.1725754 | C56: 0.026355931 | D56: 0.061811643 | E56: 71.976961 | F56: 0.1329259 | G56: 0.6 | H56: 0.024689869 | I56: 1.5519439 | J56: 0 | K56: 0.050779405 | L56: 0 | M56: 1.1834143e+08 | N56: 0 | O56: TRUE
A57: ALNY | B57: 17.39717 | C57: 0.043013326 | D57: 0.032636107 | E57: 32.663327 | F57: -0.084310618 | G57: 0 | H57: -0.13963751 | I57: 0.46145456 | J57: -0.14542881 | K57: -0.025890513 | L57: 0 | M57: 2.935563e+08 | N57: 0 | O57: TRUE
A58: ALSN | B58: 2.5945938 | C58: 0.026500704 | D58: 0.050840291 | E58: 78.287286 | F58: 0.18962628 | G58: 0.6 | H58: 0.045701693 | I58: 0.74782294 | J58: 0 | K58: 0.047268301 | L58: 0 | M58: 70300771 | N58: 0 | O58: FALSE
A59: ALV | B59: 2.656074 | C59: 0.022329707 | D59: 0.036789185 | E59: 53.654323 | F59: -0.020028176 | G59: 0.4 | H59: -0.12020705 | I59: 0.93215979 | J59: -0.037263662 | K59: 0.032561612 | L59: 0 | M59: 70430079 | N59: 0 | O59: FALSE
A60: AM | B60: 0.39361313 | C60: 0.021901709 | D60: 0.03902781 | E60: 53.213485 | F60: 0.019046377 | G60: 0.6 | H60: -0.062367095 | I60: 0.37423188 | J60: -0.026235371 | K60: -0.020994487 | L60: 0 | M60: 42970502 | N60: 0 | O60: FALSE
... A70: AMP | B70: 10.959001 | C70: 0.022103896 | D70: 0.044262245 | E70: 72.188704 | F70: 0.082647119 | G70: 0.8 | H70: -0.059301714 | I70: 0.96666009 | J70: 0 | K70: 0.039836326 | L70: 0 | M70: 2.3596077e+08 | N70: 0 | O70: TRUE
A71: AMRZ | B71: 1.3083807 | C71: 0.023993777 | D71: 0.029506694 | E71: 65.747082 | F71: 0.1187936 | G71: 0.8 | H71: -0.055021344 | I71: 0.97504729 | J71: -0.0038363171 | K71: 0.019061858 | O71: FALSE
A72: AMT | B72: 3.7914194 | C72: 0.021237708 | D72: 0.017084633 | E72: 48.658158 | F72: 0.0030058206 | G72: 0.8 | H72: -0.13012311 | I72: -0.074914774 | J72: -0.024512456 | K72: 0.0039534361 | L72: 0 | M72: 5.1142434e+08 | N72: 0 | O72: TRUE
A73: AMTM | B73: 1.3053988 | C73: 0.044101309 | D73: 0.0375 | E73: 68.453992 | F73: 0.29767646 | G73: 0.6 | H73: 0.089411721 | I73: 1.8081031 | J73: -0.013333333 | K73: 0.026352288 | L73: 0 | M73: 41262206 | N73: 0 | O73: FALSE
A74: AMX | B74: 0.47628752 | C74: 0.022360917 | D74: 0.014553991 | E74: 34.128571 | F74: -0.07951599 | G74: 0.4 | H74: 0.0093961985 | I74: 0.2403472 | J74: -0.093617021 | K74: 0.0014104372 | L74: 0 | M74: 32679299 | N74: 0 | O74: FALSE
A75: AMZN | B75: 5.5891167 | C75: 0.024113887 | D75: 0.019414962 | E75: 51.415344 | F75: -0.066908213 | G75: 0.6 | H75: -0.025553984 | I75: 1.7238546 | J75: -0.069530309 | K75: 0.016935767 | L75: 0 | M75: 8569014765 | N75: 0 | O75: TRUE
A76: AN | B76: 5.4002888 | C76: 0.024357443 | D76: 0.028956745 | E76: 67.485818 | F76: 0.14899461 | G76: 0.8 | H76: -0.060446446 | I76: 0.44155853 | J76: 0 | K76: 0.02810109 | L76: 0 | M76: 80850060 | N76: 0 | O76: FALSE
A77: ANET | B77: 5.2083882 | C77: 0.039350168 | D77: 0.033242672 | E77: 50.636748 | F77: -0.035698674 | G77: 1 | H77: -0.096135424 | I77: 1.6611388 | J77: -0.019410283 | K77: 0.017840664 | L77: 0 | M77: 959321344 | N77: 0 | O77: TRUE
A78: AON | B78: 6.2433923 | C78: 0.018360218 | D78: 0.029378033 | E78: 41.474054 | F78: -0.013976281 | G78: 0.4 | H78: -0.14809603 | I78: -0.1162655 | J78: -0.039189647 | K78: -0.017735925 | L78: 0 | M78: 4.0923469e+08 | N78: 0 | O78: TRUE
A79: AOS | B79: 1.4215944 | C79: 0.020930424 | D79: 0.026354535 | E79: 57.247033 | F79: 0.02644703 | G79: 0.4 | H79: -0.15713614 | I79: 0.59459722 | J79: -0.0016169337 | K79: 0.022429625 | L79: 0 | M79: 85159694 | N79: 0 | O79: FALSE
A80: APA | B80: 0.97606372 | C80: 0.037437096 | D80: 0.026595479 | E80: 60.44262 | F80: 0.080905948 | G80: 0.4 | H80: 0.068915448 | I80: 0.62539743 | J80: -0.028780355 | K80: -0.0026509674 | L80: 0 | M80: 1.4575631e+08 | N80: 0 | O80: TRUE
A81: APD | B81: 7.2052755 | C81: 0.030661399 | D81: 0.034345412 | E81: 35.181196 | F81: -0.084043702 | G81: 0.4 | H81: -0.18723761 | I81: 0.43610924 | J81: -0.10006357 | K81: 0.025784851 | L81: 0 | M81: 3.0570271e+08 | N81: 0 | O81: TRUE
A82: APG | B82: 1.0324436 | C82: 0.025856339 | D82: 0.059353869 | E82: 63.645346 | F82: 0.061121446 | G82: 0.6 | H82: 0.078250617 | I82: 1.3506251 | J82: 0 | K82: 0.059151194 | L82: 0 | M82: 69942228 | N82: 0 | O82: FALSE
...

Sheet FULL_RANKING
A1: Ticker | B1: Strategy_Score | C1: Lookback_Return_Ann | D1: Lookback_ATRP | E1: Was_Dropped | G1: Date | H1: PSLV_retn | I1: RBRK_retn | J1: PSLV_ATRP | K1: RBRK_ATRP
A2: SHV | B2: 0.95657722 | C2: 0.046139815 | D2: 0.00019140588 | E2: FALSE | G2: 45986 | J2: 0.029130327 | K2: 0.048618633
A3: CFLT | B3: 0.80342188 | C3: 8.9628194 | D3: 0.044269075 | E3: FALSE | G3: 45987 | H3: 0.036363636 | I3: -0.010451444 | J3: 0.028728018 | K3: 0.047068661
A4: SGOV | B4: 0.77779858 | C4: 0.038384814 | D4: 0.00019583565 | E4: FALSE | G4: 45989 | H4: 0.055461234 | I4: 0.016869591 | J4: 0.029219123 | K4: 0.045083586
A5: BIL | B5: 0.74474593 | C5: 0.041575561 | D5: 0.00022152841 | E5: FALSE | G5: 45992 | H5: 0.03538874 | I5: -0.010386613 | J5: 0.029755775 | K5: 0.044856856
A6: WBD | B6: 0.74282696 | C6: 6.4852986 | D6: 0.034645097 | E6: FALSE | G6: 45993 | H6: 0.015535992 | I6: 0.011661808 | J6: 0.029393139 | K6: 0.043457538
A7: TD | B7: 0.71614178 | C7: 2.6285048 | D7: 0.014564958 | E7: FALSE | G7: 45994 | H7: 0 | I7: 0.028962536 | J7: 0.028604913 | K7: 0.04245843
A8: MCHP | B8: 0.70179493 | C8: 7.0490947 | D8: 0.039858649 | E8: FALSE | G8: 45995 | H8: -0.029066803 | I8: -0.013723568 | J8: 0.030245538 | K8: 0.042286601
A9: SLV | B9: 0.67397835 | C9: 4.7363484 | D9: 0.027886702 | E9: FALSE | G9: 45996 | H9: 0.023109244 | I9: 0.22490416 | J9: 0.029907508 | K9: 0.048475044
A10: DG | B10: 0.66862304 | C10: 5.0779852 | D10: 0.030137662 | E10: FALSE | G10: 45999 | H10: -0.0051334702 | I10: 0.032803987 | J10: 0.02890969 | K10: 0.047478954
A11: MINT | B11: 0.66374078 | C11: 0.042656158 | D11: 0.00025502497 | E11: FALSE | G11: 46000 | H11: 0.035603715 | I11: 0.024803591 | J11: 0.02848426 | K11: 0.046540726
A12: PSLV | B12: 0.65245413 | C12: 4.7925881 | D12: 0.029148726 | E12: FALSE | G12: 46001 | H12: 0.022919781 | I12: -0.015332384 | J12: 0.028257701 | K12: 0.046458552
A13: RBRK | B13: 0.63471212 | C13: 7.3108139 | D13: 0.045707598 | E13: FALSE | G13: average | H13: =AVERAGE(H3:H12) -> 0.019018207 | I13: =AVERAGE(I3:I12) -> 0.029011166 | J13: =AVERAGE(J2:J12) -> 0.029148726 | K13: =AVERAGE(K2:K12) -> 0.045707598
A14: PATH | B14: 0.63041848 | C14: 8.6892818 | D14: 0.054695854 | E14: FALSE | G14: trading days per year | H14: 252 | I14: 252
A15: BHP | B15: 0.62176812 | C15: 3.0641254 | D15: 0.019555888 | E15: FALSE | G15: =C1 -> Lookback_Return_Ann | H15: =H13*H14 -> 4.7925881 | I15: =I13*I14 -> 7.3108139
A16: NXPI | B16: 0.62170251 | C16: 5.0068683 | D16: 0.031958251 | E16: FALSE | G16: Strategy_Score | H16: =H13/J13 -> 0.65245413 | I16: =I13/K13 -> 0.63471212
A17: TEVA | B17: 0.61886381 | C17: 4.5222653 | D17: 0.02899749 | E17: FALSE
A18: MIDD | B18: 0.60975778 | C18: 4.7432692 | D18: 0.03086881 | E18: FALSE
A19: MDB | B19: 0.60866151 | C19: 6.9789001 | D19: 0.045499917 | E19: FALSE
A20: RY | B20: 0.5980956 | C20: 2.0701584 | D20: 0.013735119 | E20: FALSE
A21: CVNA | B21: 0.56484889 | C21: 7.4483678 | D21: 0.052327296 | E21: FALSE
A22: KEY | B22: 0.55479205 | C22: 3.105623 | D22: 0.02221355 | E22: FALSE
A23: STM | B23: 0.55312282 | C23: 4.0877227 | D23: 0.029326438 | E23: FALSE
A24: JBHT | B24: 0.54435249 | C24: 3.6144356 | D24: 0.026348733 | E24: FALSE
A25: FLEX | B25: 0.54105486 | C25: 5.943243 | D25: 0.043589475 | E25: FALSE
A26: STZ | B26: 0.5381326 | C26: 2.9731688 | D26: 0.021924501 | E26: FALSE
A27: BOXX | B27: 0.53589168 | C27: 0.041782175 | D27: 0.00030939514 | E27: FALSE
A28: ENTG | B28: 0.52781041 | C28: 6.4713622 | D28: 0.048653851 | E28: FALSE
... A937: WRB | B937: -0.6435659 | C937: -3.4843146 | D937: 0.021484428 | E937: FALSE
